(11.02.21.31)Login to (1/1 account)
(11.02.21.31)Error in login new account: Traceback (most recent call last):
  File "/Users/lucabertini/Documents/GitHub/RT/riffusion_api/riffusion_api/api.py", line 100, in create_account_database
    new_account = RiffusionAccount(sb_api_auth_token_0)
                  ^^^^^^^^^^^^^^^^^^^^^^^^^^^^^^^^^^^^^
  File "/Users/lucabertini/Documents/GitHub/RT/riffusion_api/riffusion_api/_types/types.py", line 109, in __init__
    self.login_info = RiffusionLoginInfo(sb_api_auth_token_0.replace("base64-", ""))
                      ^^^^^^^^^^^^^^^^^^^^^^^^^^^^^^^^^^^^^^^^^^^^^^^^^^^^^^^^^^^^^^
  File "/Users/lucabertini/Documents/GitHub/RT/riffusion_api/riffusion_api/_types/types.py", line 91, in __init__
    json_data = decode_and_parse_invalid_base64(data)
                ^^^^^^^^^^^^^^^^^^^^^^^^^^^^^^^^^^^^^
  File "/Users/lucabertini/Documents/GitHub/RT/riffusion_api/riffusion_api/s_utils.py", line 31, in decode_and_parse_invalid_base64
    parsed_data = json.loads(decoded_str)
                  ^^^^^^^^^^^^^^^^^^^^^^^
  File "/opt/homebrew/Cellar/python@3.12/3.12.9/Frameworks/Python.framework/Versions/3.12/lib/python3.12/json/__init__.py", line 346, in loads
    return _default_decoder.decode(s)
           ^^^^^^^^^^^^^^^^^^^^^^^^^^
  File "/opt/homebrew/Cellar/python@3.12/3.12.9/Frameworks/Python.framework/Versions/3.12/lib/python3.12/json/decoder.py", line 338, in decode
    obj, end = self.raw_decode(s, idx=_w(s, 0).end())
               ^^^^^^^^^^^^^^^^^^^^^^^^^^^^^^^^^^^^^^
  File "/opt/homebrew/Cellar/python@3.12/3.12.9/Frameworks/Python.framework/Versions/3.12/lib/python3.12/json/decoder.py", line 356, in raw_decode
    raise JSONDecodeError("Expecting value", s, err.value) from None
json.decoder.JSONDecodeError: Expecting value: line 1 column 1 (char 0)

(11.02.21.38)Login to (1/1 account)
(11.02.21.38)Error in login new account: Traceback (most recent call last):
  File "/Users/lucabertini/Documents/GitHub/RT/riffusion_api/riffusion_api/api.py", line 100, in create_account_database
    new_account = RiffusionAccount(sb_api_auth_token_0)
                  ^^^^^^^^^^^^^^^^^^^^^^^^^^^^^^^^^^^^^
  File "/Users/lucabertini/Documents/GitHub/RT/riffusion_api/riffusion_api/_types/types.py", line 109, in __init__
    self.login_info = RiffusionLoginInfo(sb_api_auth_token_0.replace("base64-", ""))
                      ^^^^^^^^^^^^^^^^^^^^^^^^^^^^^^^^^^^^^^^^^^^^^^^^^^^^^^^^^^^^^^
  File "/Users/lucabertini/Documents/GitHub/RT/riffusion_api/riffusion_api/_types/types.py", line 91, in __init__
    json_data = decode_and_parse_invalid_base64(data)
                ^^^^^^^^^^^^^^^^^^^^^^^^^^^^^^^^^^^^^
  File "/Users/lucabertini/Documents/GitHub/RT/riffusion_api/riffusion_api/s_utils.py", line 31, in decode_and_parse_invalid_base64
    parsed_data = json.loads(decoded_str)
                  ^^^^^^^^^^^^^^^^^^^^^^^
  File "/opt/homebrew/Cellar/python@3.12/3.12.9/Frameworks/Python.framework/Versions/3.12/lib/python3.12/json/__init__.py", line 346, in loads
    return _default_decoder.decode(s)
           ^^^^^^^^^^^^^^^^^^^^^^^^^^
  File "/opt/homebrew/Cellar/python@3.12/3.12.9/Frameworks/Python.framework/Versions/3.12/lib/python3.12/json/decoder.py", line 341, in decode
    raise JSONDecodeError("Extra data", s, end)
json.decoder.JSONDecodeError: Extra data: line 1 column 28 (char 27)

(11.02.21.38)Login to (1/1 account)
(11.02.21.38)Error in login new account: Traceback (most recent call last):
  File "/Users/lucabertini/Documents/GitHub/RT/riffusion_api/riffusion_api/api.py", line 100, in create_account_database
    new_account = RiffusionAccount(sb_api_auth_token_0)
                  ^^^^^^^^^^^^^^^^^^^^^^^^^^^^^^^^^^^^^
  File "/Users/lucabertini/Documents/GitHub/RT/riffusion_api/riffusion_api/_types/types.py", line 109, in __init__
    self.login_info = RiffusionLoginInfo(sb_api_auth_token_0.replace("base64-", ""))
                      ^^^^^^^^^^^^^^^^^^^^^^^^^^^^^^^^^^^^^^^^^^^^^^^^^^^^^^^^^^^^^^
  File "/Users/lucabertini/Documents/GitHub/RT/riffusion_api/riffusion_api/_types/types.py", line 91, in __init__
    json_data = decode_and_parse_invalid_base64(data)
                ^^^^^^^^^^^^^^^^^^^^^^^^^^^^^^^^^^^^^
  File "/Users/lucabertini/Documents/GitHub/RT/riffusion_api/riffusion_api/s_utils.py", line 31, in decode_and_parse_invalid_base64
    parsed_data = json.loads(decoded_str)
                  ^^^^^^^^^^^^^^^^^^^^^^^
  File "/opt/homebrew/Cellar/python@3.12/3.12.9/Frameworks/Python.framework/Versions/3.12/lib/python3.12/json/__init__.py", line 346, in loads
    return _default_decoder.decode(s)
           ^^^^^^^^^^^^^^^^^^^^^^^^^^
  File "/opt/homebrew/Cellar/python@3.12/3.12.9/Frameworks/Python.framework/Versions/3.12/lib/python3.12/json/decoder.py", line 338, in decode
    obj, end = self.raw_decode(s, idx=_w(s, 0).end())
               ^^^^^^^^^^^^^^^^^^^^^^^^^^^^^^^^^^^^^^
  File "/opt/homebrew/Cellar/python@3.12/3.12.9/Frameworks/Python.framework/Versions/3.12/lib/python3.12/json/decoder.py", line 356, in raw_decode
    raise JSONDecodeError("Expecting value", s, err.value) from None
json.decoder.JSONDecodeError: Expecting value: line 1 column 1 (char 0)

(11.02.21.39)Login to (1/1 account)
(11.02.21.39)Error in login new account: Traceback (most recent call last):
  File "/Users/lucabertini/Documents/GitHub/RT/riffusion_api/riffusion_api/api.py", line 100, in create_account_database
    new_account = RiffusionAccount(sb_api_auth_token_0)
                  ^^^^^^^^^^^^^^^^^^^^^^^^^^^^^^^^^^^^^
  File "/Users/lucabertini/Documents/GitHub/RT/riffusion_api/riffusion_api/_types/types.py", line 109, in __init__
    self.login_info = RiffusionLoginInfo(sb_api_auth_token_0.replace("base64-", ""))
                      ^^^^^^^^^^^^^^^^^^^^^^^^^^^^^^^^^^^^^^^^^^^^^^^^^^^^^^^^^^^^^^
  File "/Users/lucabertini/Documents/GitHub/RT/riffusion_api/riffusion_api/_types/types.py", line 91, in __init__
    json_data = decode_and_parse_invalid_base64(data)
                ^^^^^^^^^^^^^^^^^^^^^^^^^^^^^^^^^^^^^
  File "/Users/lucabertini/Documents/GitHub/RT/riffusion_api/riffusion_api/s_utils.py", line 31, in decode_and_parse_invalid_base64
    parsed_data = json.loads(decoded_str)
                  ^^^^^^^^^^^^^^^^^^^^^^^
  File "/opt/homebrew/Cellar/python@3.12/3.12.9/Frameworks/Python.framework/Versions/3.12/lib/python3.12/json/__init__.py", line 346, in loads
    return _default_decoder.decode(s)
           ^^^^^^^^^^^^^^^^^^^^^^^^^^
  File "/opt/homebrew/Cellar/python@3.12/3.12.9/Frameworks/Python.framework/Versions/3.12/lib/python3.12/json/decoder.py", line 341, in decode
    raise JSONDecodeError("Extra data", s, end)
json.decoder.JSONDecodeError: Extra data: line 1 column 28 (char 27)

(11.02.21.42)Login to (1/1 account)
(11.02.21.42)Add new account: lucabertiniluca@gmail.com
(11.02.21.42)saved 1 accounts
(11.02.21.42)Selected: lucabertiniluca@gmail.com
(11.02.21.50)Skip refresh lucabertiniluca@gmail.com
(11.02.21.50)Login to (1/1 account)
(11.02.21.50)Skip account as exists
(11.02.21.50)saved 1 accounts
(11.02.21.50)File /Users/lucabertini/Documents/GitHub/RT/riffusion_api/song.mp3 exists. It will be removed
(11.02.21.50)Selected: lucabertiniluca@gmail.com
(11.02.22.02)Skip refresh lucabertiniluca@gmail.com
(11.02.22.02)Login to (1/1 account)
(11.02.22.02)Skip account as exists
(11.02.22.02)saved 1 accounts
(11.02.22.02)File /Users/lucabertini/Documents/GitHub/RT/riffusion_api/song.mp3 exists. It will be removed
(11.02.22.02)Selected: lucabertiniluca@gmail.com
(11.02.22.08)Skip refresh lucabertiniluca@gmail.com
(11.02.22.08)Login to (1/1 account)
(11.02.22.08)Error in login new account: Traceback (most recent call last):
  File "/Users/lucabertini/Documents/GitHub/RT/riffusion_api/riffusion_api/api.py", line 100, in create_account_database
    new_account = RiffusionAccount(sb_api_auth_token_0)
                  ^^^^^^^^^^^^^^^^^^^^^^^^^^^^^^^^^^^^^
  File "/Users/lucabertini/Documents/GitHub/RT/riffusion_api/riffusion_api/_types/types.py", line 109, in __init__
    self.login_info = RiffusionLoginInfo(sb_api_auth_token_0.replace("base64-", ""))
                      ^^^^^^^^^^^^^^^^^^^^^^^^^^^^^^^^^^^^^^^^^^^^^^^^^^^^^^^^^^^^^^
  File "/Users/lucabertini/Documents/GitHub/RT/riffusion_api/riffusion_api/_types/types.py", line 91, in __init__
    json_data = decode_and_parse_invalid_base64(data)
                ^^^^^^^^^^^^^^^^^^^^^^^^^^^^^^^^^^^^^
  File "/Users/lucabertini/Documents/GitHub/RT/riffusion_api/riffusion_api/s_utils.py", line 31, in decode_and_parse_invalid_base64
    parsed_data = json.loads(decoded_str)
                  ^^^^^^^^^^^^^^^^^^^^^^^
  File "/opt/homebrew/Cellar/python@3.12/3.12.9/Frameworks/Python.framework/Versions/3.12/lib/python3.12/json/__init__.py", line 346, in loads
    return _default_decoder.decode(s)
           ^^^^^^^^^^^^^^^^^^^^^^^^^^
  File "/opt/homebrew/Cellar/python@3.12/3.12.9/Frameworks/Python.framework/Versions/3.12/lib/python3.12/json/decoder.py", line 338, in decode
    obj, end = self.raw_decode(s, idx=_w(s, 0).end())
               ^^^^^^^^^^^^^^^^^^^^^^^^^^^^^^^^^^^^^^
  File "/opt/homebrew/Cellar/python@3.12/3.12.9/Frameworks/Python.framework/Versions/3.12/lib/python3.12/json/decoder.py", line 354, in raw_decode
    obj, end = self.scan_once(s, idx)
               ^^^^^^^^^^^^^^^^^^^^^^
json.decoder.JSONDecodeError: Expecting property name enclosed in double quotes: line 1 column 1726 (char 1725)

(11.02.22.08)saved 1 accounts
(11.02.22.08)File /Users/lucabertini/Documents/GitHub/RT/riffusion_api/song.mp3 exists. It will be removed
(11.02.22.08)Selected: lucabertiniluca@gmail.com
(11.02.22.08)Skip refresh lucabertiniluca@gmail.com
(11.02.22.08)Login to (1/1 account)
(11.02.22.08)Skip account as exists
(11.02.22.08)saved 1 accounts
(11.02.22.08)File /Users/lucabertini/Documents/GitHub/RT/riffusion_api/song.mp3 exists. It will be removed
(11.02.22.08)Selected: lucabertiniluca@gmail.com
(11.02.22.12)Skip refresh lucabertiniluca@gmail.com
(11.02.22.12)Login to (1/1 account)
(11.02.22.12)Skip account as exists
(11.02.22.12)saved 1 accounts
(11.02.22.12)File /Users/lucabertini/Documents/GitHub/RT/riffusion_api/song.mp3 exists. It will be removed
(11.02.22.12)Selected: lucabertiniluca@gmail.com
(11.02.22.12)Error 1/10 while generation: Traceback (most recent call last):
  File "/Users/lucabertini/Documents/GitHub/RT/riffusion_api/venv/lib/python3.12/site-packages/requests/models.py", line 974, in json
    return complexjson.loads(self.text, **kwargs)
           ^^^^^^^^^^^^^^^^^^^^^^^^^^^^^^^^^^^^^^
  File "/opt/homebrew/Cellar/python@3.12/3.12.9/Frameworks/Python.framework/Versions/3.12/lib/python3.12/json/__init__.py", line 346, in loads
    return _default_decoder.decode(s)
           ^^^^^^^^^^^^^^^^^^^^^^^^^^
  File "/opt/homebrew/Cellar/python@3.12/3.12.9/Frameworks/Python.framework/Versions/3.12/lib/python3.12/json/decoder.py", line 338, in decode
    obj, end = self.raw_decode(s, idx=_w(s, 0).end())
               ^^^^^^^^^^^^^^^^^^^^^^^^^^^^^^^^^^^^^^
  File "/opt/homebrew/Cellar/python@3.12/3.12.9/Frameworks/Python.framework/Versions/3.12/lib/python3.12/json/decoder.py", line 356, in raw_decode
    raise JSONDecodeError("Expecting value", s, err.value) from None
json.decoder.JSONDecodeError: Expecting value: line 2 column 1 (char 1)

During handling of the above exception, another exception occurred:

Traceback (most recent call last):
  File "/Users/lucabertini/Documents/GitHub/RT/riffusion_api/riffusion_api/api.py", line 422, in generate
    json_data = response.json()
                ^^^^^^^^^^^^^^^
  File "/Users/lucabertini/Documents/GitHub/RT/riffusion_api/venv/lib/python3.12/site-packages/requests/models.py", line 978, in json
    raise RequestsJSONDecodeError(e.msg, e.doc, e.pos)
requests.exceptions.JSONDecodeError: Expecting value: line 2 column 1 (char 1)

(11.02.22.12)Selected: lucabertiniluca@gmail.com
(11.02.22.13)Skip refresh lucabertiniluca@gmail.com
(11.02.22.13)Login to (1/1 account)
(11.02.22.13)Skip account as exists
(11.02.22.13)saved 1 accounts
(11.02.22.13)File /Users/lucabertini/Documents/GitHub/RT/riffusion_api/song.mp3 exists. It will be removed
(11.02.22.13)Selected: lucabertiniluca@gmail.com
(11.02.22.15)Skip refresh lucabertiniluca@gmail.com
(11.02.22.15)Login to (1/1 account)
(11.02.22.15)Skip account as exists
(11.02.22.15)saved 1 accounts
(11.02.22.15)File /Users/lucabertini/Documents/GitHub/RT/riffusion_api/song.mp3 exists. It will be removed
(11.02.22.15)Selected: lucabertiniluca@gmail.com
(11.02.22.16)Error 1/10 while generation: Traceback (most recent call last):
  File "/Users/lucabertini/Documents/GitHub/RT/riffusion_api/venv/lib/python3.12/site-packages/requests/models.py", line 974, in json
    return complexjson.loads(self.text, **kwargs)
           ^^^^^^^^^^^^^^^^^^^^^^^^^^^^^^^^^^^^^^
  File "/opt/homebrew/Cellar/python@3.12/3.12.9/Frameworks/Python.framework/Versions/3.12/lib/python3.12/json/__init__.py", line 346, in loads
    return _default_decoder.decode(s)
           ^^^^^^^^^^^^^^^^^^^^^^^^^^
  File "/opt/homebrew/Cellar/python@3.12/3.12.9/Frameworks/Python.framework/Versions/3.12/lib/python3.12/json/decoder.py", line 338, in decode
    obj, end = self.raw_decode(s, idx=_w(s, 0).end())
               ^^^^^^^^^^^^^^^^^^^^^^^^^^^^^^^^^^^^^^
  File "/opt/homebrew/Cellar/python@3.12/3.12.9/Frameworks/Python.framework/Versions/3.12/lib/python3.12/json/decoder.py", line 356, in raw_decode
    raise JSONDecodeError("Expecting value", s, err.value) from None
json.decoder.JSONDecodeError: Expecting value: line 2 column 1 (char 1)

During handling of the above exception, another exception occurred:

Traceback (most recent call last):
  File "/Users/lucabertini/Documents/GitHub/RT/riffusion_api/riffusion_api/api.py", line 422, in generate
    json_data = response.json()
                ^^^^^^^^^^^^^^^
  File "/Users/lucabertini/Documents/GitHub/RT/riffusion_api/venv/lib/python3.12/site-packages/requests/models.py", line 978, in json
    raise RequestsJSONDecodeError(e.msg, e.doc, e.pos)
requests.exceptions.JSONDecodeError: Expecting value: line 2 column 1 (char 1)

(11.02.22.16)Selected: lucabertiniluca@gmail.com
(11.02.22.16)Error 2/10 while generation: Traceback (most recent call last):
  File "/Users/lucabertini/Documents/GitHub/RT/riffusion_api/venv/lib/python3.12/site-packages/requests/models.py", line 974, in json
    return complexjson.loads(self.text, **kwargs)
           ^^^^^^^^^^^^^^^^^^^^^^^^^^^^^^^^^^^^^^
  File "/opt/homebrew/Cellar/python@3.12/3.12.9/Frameworks/Python.framework/Versions/3.12/lib/python3.12/json/__init__.py", line 346, in loads
    return _default_decoder.decode(s)
           ^^^^^^^^^^^^^^^^^^^^^^^^^^
  File "/opt/homebrew/Cellar/python@3.12/3.12.9/Frameworks/Python.framework/Versions/3.12/lib/python3.12/json/decoder.py", line 338, in decode
    obj, end = self.raw_decode(s, idx=_w(s, 0).end())
               ^^^^^^^^^^^^^^^^^^^^^^^^^^^^^^^^^^^^^^
  File "/opt/homebrew/Cellar/python@3.12/3.12.9/Frameworks/Python.framework/Versions/3.12/lib/python3.12/json/decoder.py", line 356, in raw_decode
    raise JSONDecodeError("Expecting value", s, err.value) from None
json.decoder.JSONDecodeError: Expecting value: line 2 column 1 (char 1)

During handling of the above exception, another exception occurred:

Traceback (most recent call last):
  File "/Users/lucabertini/Documents/GitHub/RT/riffusion_api/riffusion_api/api.py", line 422, in generate
    json_data = response.json()
                ^^^^^^^^^^^^^^^
  File "/Users/lucabertini/Documents/GitHub/RT/riffusion_api/venv/lib/python3.12/site-packages/requests/models.py", line 978, in json
    raise RequestsJSONDecodeError(e.msg, e.doc, e.pos)
requests.exceptions.JSONDecodeError: Expecting value: line 2 column 1 (char 1)

(11.02.22.16)Selected: lucabertiniluca@gmail.com
(11.02.22.16)Error 3/10 while generation: Traceback (most recent call last):
  File "/Users/lucabertini/Documents/GitHub/RT/riffusion_api/venv/lib/python3.12/site-packages/requests/models.py", line 974, in json
    return complexjson.loads(self.text, **kwargs)
           ^^^^^^^^^^^^^^^^^^^^^^^^^^^^^^^^^^^^^^
  File "/opt/homebrew/Cellar/python@3.12/3.12.9/Frameworks/Python.framework/Versions/3.12/lib/python3.12/json/__init__.py", line 346, in loads
    return _default_decoder.decode(s)
           ^^^^^^^^^^^^^^^^^^^^^^^^^^
  File "/opt/homebrew/Cellar/python@3.12/3.12.9/Frameworks/Python.framework/Versions/3.12/lib/python3.12/json/decoder.py", line 338, in decode
    obj, end = self.raw_decode(s, idx=_w(s, 0).end())
               ^^^^^^^^^^^^^^^^^^^^^^^^^^^^^^^^^^^^^^
  File "/opt/homebrew/Cellar/python@3.12/3.12.9/Frameworks/Python.framework/Versions/3.12/lib/python3.12/json/decoder.py", line 356, in raw_decode
    raise JSONDecodeError("Expecting value", s, err.value) from None
json.decoder.JSONDecodeError: Expecting value: line 2 column 1 (char 1)

During handling of the above exception, another exception occurred:

Traceback (most recent call last):
  File "/Users/lucabertini/Documents/GitHub/RT/riffusion_api/riffusion_api/api.py", line 422, in generate
    json_data = response.json()
                ^^^^^^^^^^^^^^^
  File "/Users/lucabertini/Documents/GitHub/RT/riffusion_api/venv/lib/python3.12/site-packages/requests/models.py", line 978, in json
    raise RequestsJSONDecodeError(e.msg, e.doc, e.pos)
requests.exceptions.JSONDecodeError: Expecting value: line 2 column 1 (char 1)

(11.02.22.16)Selected: lucabertiniluca@gmail.com
(11.02.22.16)Error 4/10 while generation: Traceback (most recent call last):
  File "/Users/lucabertini/Documents/GitHub/RT/riffusion_api/venv/lib/python3.12/site-packages/requests/models.py", line 974, in json
    return complexjson.loads(self.text, **kwargs)
           ^^^^^^^^^^^^^^^^^^^^^^^^^^^^^^^^^^^^^^
  File "/opt/homebrew/Cellar/python@3.12/3.12.9/Frameworks/Python.framework/Versions/3.12/lib/python3.12/json/__init__.py", line 346, in loads
    return _default_decoder.decode(s)
           ^^^^^^^^^^^^^^^^^^^^^^^^^^
  File "/opt/homebrew/Cellar/python@3.12/3.12.9/Frameworks/Python.framework/Versions/3.12/lib/python3.12/json/decoder.py", line 338, in decode
    obj, end = self.raw_decode(s, idx=_w(s, 0).end())
               ^^^^^^^^^^^^^^^^^^^^^^^^^^^^^^^^^^^^^^
  File "/opt/homebrew/Cellar/python@3.12/3.12.9/Frameworks/Python.framework/Versions/3.12/lib/python3.12/json/decoder.py", line 356, in raw_decode
    raise JSONDecodeError("Expecting value", s, err.value) from None
json.decoder.JSONDecodeError: Expecting value: line 2 column 1 (char 1)

During handling of the above exception, another exception occurred:

Traceback (most recent call last):
  File "/Users/lucabertini/Documents/GitHub/RT/riffusion_api/riffusion_api/api.py", line 422, in generate
    json_data = response.json()
                ^^^^^^^^^^^^^^^
  File "/Users/lucabertini/Documents/GitHub/RT/riffusion_api/venv/lib/python3.12/site-packages/requests/models.py", line 978, in json
    raise RequestsJSONDecodeError(e.msg, e.doc, e.pos)
requests.exceptions.JSONDecodeError: Expecting value: line 2 column 1 (char 1)

(11.02.22.16)Selected: lucabertiniluca@gmail.com
(11.02.22.16)Error 5/10 while generation: Traceback (most recent call last):
  File "/Users/lucabertini/Documents/GitHub/RT/riffusion_api/venv/lib/python3.12/site-packages/requests/models.py", line 974, in json
    return complexjson.loads(self.text, **kwargs)
           ^^^^^^^^^^^^^^^^^^^^^^^^^^^^^^^^^^^^^^
  File "/opt/homebrew/Cellar/python@3.12/3.12.9/Frameworks/Python.framework/Versions/3.12/lib/python3.12/json/__init__.py", line 346, in loads
    return _default_decoder.decode(s)
           ^^^^^^^^^^^^^^^^^^^^^^^^^^
  File "/opt/homebrew/Cellar/python@3.12/3.12.9/Frameworks/Python.framework/Versions/3.12/lib/python3.12/json/decoder.py", line 338, in decode
    obj, end = self.raw_decode(s, idx=_w(s, 0).end())
               ^^^^^^^^^^^^^^^^^^^^^^^^^^^^^^^^^^^^^^
  File "/opt/homebrew/Cellar/python@3.12/3.12.9/Frameworks/Python.framework/Versions/3.12/lib/python3.12/json/decoder.py", line 356, in raw_decode
    raise JSONDecodeError("Expecting value", s, err.value) from None
json.decoder.JSONDecodeError: Expecting value: line 2 column 1 (char 1)

During handling of the above exception, another exception occurred:

Traceback (most recent call last):
  File "/Users/lucabertini/Documents/GitHub/RT/riffusion_api/riffusion_api/api.py", line 422, in generate
    json_data = response.json()
                ^^^^^^^^^^^^^^^
  File "/Users/lucabertini/Documents/GitHub/RT/riffusion_api/venv/lib/python3.12/site-packages/requests/models.py", line 978, in json
    raise RequestsJSONDecodeError(e.msg, e.doc, e.pos)
requests.exceptions.JSONDecodeError: Expecting value: line 2 column 1 (char 1)

(11.02.22.16)Selected: lucabertiniluca@gmail.com
(11.02.22.16)Error 6/10 while generation: Traceback (most recent call last):
  File "/Users/lucabertini/Documents/GitHub/RT/riffusion_api/venv/lib/python3.12/site-packages/requests/models.py", line 974, in json
    return complexjson.loads(self.text, **kwargs)
           ^^^^^^^^^^^^^^^^^^^^^^^^^^^^^^^^^^^^^^
  File "/opt/homebrew/Cellar/python@3.12/3.12.9/Frameworks/Python.framework/Versions/3.12/lib/python3.12/json/__init__.py", line 346, in loads
    return _default_decoder.decode(s)
           ^^^^^^^^^^^^^^^^^^^^^^^^^^
  File "/opt/homebrew/Cellar/python@3.12/3.12.9/Frameworks/Python.framework/Versions/3.12/lib/python3.12/json/decoder.py", line 338, in decode
    obj, end = self.raw_decode(s, idx=_w(s, 0).end())
               ^^^^^^^^^^^^^^^^^^^^^^^^^^^^^^^^^^^^^^
  File "/opt/homebrew/Cellar/python@3.12/3.12.9/Frameworks/Python.framework/Versions/3.12/lib/python3.12/json/decoder.py", line 356, in raw_decode
    raise JSONDecodeError("Expecting value", s, err.value) from None
json.decoder.JSONDecodeError: Expecting value: line 2 column 1 (char 1)

During handling of the above exception, another exception occurred:

Traceback (most recent call last):
  File "/Users/lucabertini/Documents/GitHub/RT/riffusion_api/riffusion_api/api.py", line 422, in generate
    json_data = response.json()
                ^^^^^^^^^^^^^^^
  File "/Users/lucabertini/Documents/GitHub/RT/riffusion_api/venv/lib/python3.12/site-packages/requests/models.py", line 978, in json
    raise RequestsJSONDecodeError(e.msg, e.doc, e.pos)
requests.exceptions.JSONDecodeError: Expecting value: line 2 column 1 (char 1)

(11.02.22.16)Selected: lucabertiniluca@gmail.com
(11.02.22.16)Error 7/10 while generation: Traceback (most recent call last):
  File "/Users/lucabertini/Documents/GitHub/RT/riffusion_api/venv/lib/python3.12/site-packages/requests/models.py", line 974, in json
    return complexjson.loads(self.text, **kwargs)
           ^^^^^^^^^^^^^^^^^^^^^^^^^^^^^^^^^^^^^^
  File "/opt/homebrew/Cellar/python@3.12/3.12.9/Frameworks/Python.framework/Versions/3.12/lib/python3.12/json/__init__.py", line 346, in loads
    return _default_decoder.decode(s)
           ^^^^^^^^^^^^^^^^^^^^^^^^^^
  File "/opt/homebrew/Cellar/python@3.12/3.12.9/Frameworks/Python.framework/Versions/3.12/lib/python3.12/json/decoder.py", line 338, in decode
    obj, end = self.raw_decode(s, idx=_w(s, 0).end())
               ^^^^^^^^^^^^^^^^^^^^^^^^^^^^^^^^^^^^^^
  File "/opt/homebrew/Cellar/python@3.12/3.12.9/Frameworks/Python.framework/Versions/3.12/lib/python3.12/json/decoder.py", line 356, in raw_decode
    raise JSONDecodeError("Expecting value", s, err.value) from None
json.decoder.JSONDecodeError: Expecting value: line 2 column 1 (char 1)

During handling of the above exception, another exception occurred:

Traceback (most recent call last):
  File "/Users/lucabertini/Documents/GitHub/RT/riffusion_api/riffusion_api/api.py", line 422, in generate
    json_data = response.json()
                ^^^^^^^^^^^^^^^
  File "/Users/lucabertini/Documents/GitHub/RT/riffusion_api/venv/lib/python3.12/site-packages/requests/models.py", line 978, in json
    raise RequestsJSONDecodeError(e.msg, e.doc, e.pos)
requests.exceptions.JSONDecodeError: Expecting value: line 2 column 1 (char 1)

(11.02.22.16)Selected: lucabertiniluca@gmail.com
(11.02.22.16)Error 8/10 while generation: Traceback (most recent call last):
  File "/Users/lucabertini/Documents/GitHub/RT/riffusion_api/venv/lib/python3.12/site-packages/requests/models.py", line 974, in json
    return complexjson.loads(self.text, **kwargs)
           ^^^^^^^^^^^^^^^^^^^^^^^^^^^^^^^^^^^^^^
  File "/opt/homebrew/Cellar/python@3.12/3.12.9/Frameworks/Python.framework/Versions/3.12/lib/python3.12/json/__init__.py", line 346, in loads
    return _default_decoder.decode(s)
           ^^^^^^^^^^^^^^^^^^^^^^^^^^
  File "/opt/homebrew/Cellar/python@3.12/3.12.9/Frameworks/Python.framework/Versions/3.12/lib/python3.12/json/decoder.py", line 338, in decode
    obj, end = self.raw_decode(s, idx=_w(s, 0).end())
               ^^^^^^^^^^^^^^^^^^^^^^^^^^^^^^^^^^^^^^
  File "/opt/homebrew/Cellar/python@3.12/3.12.9/Frameworks/Python.framework/Versions/3.12/lib/python3.12/json/decoder.py", line 356, in raw_decode
    raise JSONDecodeError("Expecting value", s, err.value) from None
json.decoder.JSONDecodeError: Expecting value: line 2 column 1 (char 1)

During handling of the above exception, another exception occurred:

Traceback (most recent call last):
  File "/Users/lucabertini/Documents/GitHub/RT/riffusion_api/riffusion_api/api.py", line 422, in generate
    json_data = response.json()
                ^^^^^^^^^^^^^^^
  File "/Users/lucabertini/Documents/GitHub/RT/riffusion_api/venv/lib/python3.12/site-packages/requests/models.py", line 978, in json
    raise RequestsJSONDecodeError(e.msg, e.doc, e.pos)
requests.exceptions.JSONDecodeError: Expecting value: line 2 column 1 (char 1)

(11.02.22.16)Selected: lucabertiniluca@gmail.com
(11.02.22.16)Error 9/10 while generation: Traceback (most recent call last):
  File "/Users/lucabertini/Documents/GitHub/RT/riffusion_api/venv/lib/python3.12/site-packages/requests/models.py", line 974, in json
    return complexjson.loads(self.text, **kwargs)
           ^^^^^^^^^^^^^^^^^^^^^^^^^^^^^^^^^^^^^^
  File "/opt/homebrew/Cellar/python@3.12/3.12.9/Frameworks/Python.framework/Versions/3.12/lib/python3.12/json/__init__.py", line 346, in loads
    return _default_decoder.decode(s)
           ^^^^^^^^^^^^^^^^^^^^^^^^^^
  File "/opt/homebrew/Cellar/python@3.12/3.12.9/Frameworks/Python.framework/Versions/3.12/lib/python3.12/json/decoder.py", line 338, in decode
    obj, end = self.raw_decode(s, idx=_w(s, 0).end())
               ^^^^^^^^^^^^^^^^^^^^^^^^^^^^^^^^^^^^^^
  File "/opt/homebrew/Cellar/python@3.12/3.12.9/Frameworks/Python.framework/Versions/3.12/lib/python3.12/json/decoder.py", line 356, in raw_decode
    raise JSONDecodeError("Expecting value", s, err.value) from None
json.decoder.JSONDecodeError: Expecting value: line 2 column 1 (char 1)

During handling of the above exception, another exception occurred:

Traceback (most recent call last):
  File "/Users/lucabertini/Documents/GitHub/RT/riffusion_api/riffusion_api/api.py", line 422, in generate
    json_data = response.json()
                ^^^^^^^^^^^^^^^
  File "/Users/lucabertini/Documents/GitHub/RT/riffusion_api/venv/lib/python3.12/site-packages/requests/models.py", line 978, in json
    raise RequestsJSONDecodeError(e.msg, e.doc, e.pos)
requests.exceptions.JSONDecodeError: Expecting value: line 2 column 1 (char 1)

(11.02.22.16)Selected: lucabertiniluca@gmail.com
(11.02.22.16)Error 10/10 while generation: Traceback (most recent call last):
  File "/Users/lucabertini/Documents/GitHub/RT/riffusion_api/venv/lib/python3.12/site-packages/requests/models.py", line 974, in json
    return complexjson.loads(self.text, **kwargs)
           ^^^^^^^^^^^^^^^^^^^^^^^^^^^^^^^^^^^^^^
  File "/opt/homebrew/Cellar/python@3.12/3.12.9/Frameworks/Python.framework/Versions/3.12/lib/python3.12/json/__init__.py", line 346, in loads
    return _default_decoder.decode(s)
           ^^^^^^^^^^^^^^^^^^^^^^^^^^
  File "/opt/homebrew/Cellar/python@3.12/3.12.9/Frameworks/Python.framework/Versions/3.12/lib/python3.12/json/decoder.py", line 338, in decode
    obj, end = self.raw_decode(s, idx=_w(s, 0).end())
               ^^^^^^^^^^^^^^^^^^^^^^^^^^^^^^^^^^^^^^
  File "/opt/homebrew/Cellar/python@3.12/3.12.9/Frameworks/Python.framework/Versions/3.12/lib/python3.12/json/decoder.py", line 356, in raw_decode
    raise JSONDecodeError("Expecting value", s, err.value) from None
json.decoder.JSONDecodeError: Expecting value: line 2 column 1 (char 1)

During handling of the above exception, another exception occurred:

Traceback (most recent call last):
  File "/Users/lucabertini/Documents/GitHub/RT/riffusion_api/riffusion_api/api.py", line 422, in generate
    json_data = response.json()
                ^^^^^^^^^^^^^^^
  File "/Users/lucabertini/Documents/GitHub/RT/riffusion_api/venv/lib/python3.12/site-packages/requests/models.py", line 978, in json
    raise RequestsJSONDecodeError(e.msg, e.doc, e.pos)
requests.exceptions.JSONDecodeError: Expecting value: line 2 column 1 (char 1)

(11.02.22.17)Skip refresh lucabertiniluca@gmail.com
(11.02.22.17)Login to (1/1 account)
(11.02.22.17)Skip account as exists
(11.02.22.17)saved 1 accounts
(11.02.22.17)File /Users/lucabertini/Documents/GitHub/RT/riffusion_api/song.mp3 exists. It will be removed
(11.02.22.17)Selected: lucabertiniluca@gmail.com
(11.02.22.19)Skip refresh lucabertiniluca@gmail.com
(11.02.22.19)Login to (1/1 account)
(11.02.22.19)Skip account as exists
(11.02.22.19)saved 1 accounts
(11.02.22.19)File /Users/lucabertini/Documents/GitHub/RT/riffusion_api/song.mp3 exists. It will be removed
(11.02.22.19)Selected: lucabertiniluca@gmail.com
(11.02.22.21)Error 1/10 while generation: Traceback (most recent call last):
  File "/Users/lucabertini/Documents/GitHub/RT/riffusion_api/riffusion_api/api.py", line 423, in generate
    track = self._wait_for_generate(account=account, job_id=json_data['job_id'])
            ^^^^^^^^^^^^^^^^^^^^^^^^^^^^^^^^^^^^^^^^^^^^^^^^^^^^^^^^^^^^^^^^^^^^
  File "/Users/lucabertini/Documents/GitHub/RT/riffusion_api/riffusion_api/api.py", line 254, in _wait_for_generate
    response.raise_for_status()
  File "/Users/lucabertini/Documents/GitHub/RT/riffusion_api/venv/lib/python3.12/site-packages/requests/models.py", line 1024, in raise_for_status
    raise HTTPError(http_error_msg, response=self)
requests.exceptions.HTTPError: 502 Server Error: Bad Gateway for url: https://wb.riffusion.com/v2/generate/f155c583-f8b6-42e2-aae3-75700b2ab6e1

(11.02.22.21)Selected: lucabertiniluca@gmail.com
(11.02.22.22)Skip refresh lucabertiniluca@gmail.com
(11.02.22.22)Login to (1/1 account)
(11.02.22.22)Skip account as exists
(11.02.22.22)saved 1 accounts
(11.02.22.22)File /Users/lucabertini/Documents/GitHub/RT/riffusion_api/song.mp3 exists. It will be removed
(11.02.22.22)Selected: lucabertiniluca@gmail.com
(11.02.22.22)Error 1/10 while generation: Traceback (most recent call last):
  File "/Users/lucabertini/Documents/GitHub/RT/riffusion_api/venv/lib/python3.12/site-packages/requests/models.py", line 974, in json
    return complexjson.loads(self.text, **kwargs)
           ^^^^^^^^^^^^^^^^^^^^^^^^^^^^^^^^^^^^^^
  File "/opt/homebrew/Cellar/python@3.12/3.12.9/Frameworks/Python.framework/Versions/3.12/lib/python3.12/json/__init__.py", line 346, in loads
    return _default_decoder.decode(s)
           ^^^^^^^^^^^^^^^^^^^^^^^^^^
  File "/opt/homebrew/Cellar/python@3.12/3.12.9/Frameworks/Python.framework/Versions/3.12/lib/python3.12/json/decoder.py", line 338, in decode
    obj, end = self.raw_decode(s, idx=_w(s, 0).end())
               ^^^^^^^^^^^^^^^^^^^^^^^^^^^^^^^^^^^^^^
  File "/opt/homebrew/Cellar/python@3.12/3.12.9/Frameworks/Python.framework/Versions/3.12/lib/python3.12/json/decoder.py", line 356, in raw_decode
    raise JSONDecodeError("Expecting value", s, err.value) from None
json.decoder.JSONDecodeError: Expecting value: line 2 column 1 (char 1)

During handling of the above exception, another exception occurred:

Traceback (most recent call last):
  File "/Users/lucabertini/Documents/GitHub/RT/riffusion_api/riffusion_api/api.py", line 422, in generate
    json_data = response.json()
                ^^^^^^^^^^^^^^^
  File "/Users/lucabertini/Documents/GitHub/RT/riffusion_api/venv/lib/python3.12/site-packages/requests/models.py", line 978, in json
    raise RequestsJSONDecodeError(e.msg, e.doc, e.pos)
requests.exceptions.JSONDecodeError: Expecting value: line 2 column 1 (char 1)

(11.02.22.22)Selected: lucabertiniluca@gmail.com
(11.02.22.23)Error 2/10 while generation: Traceback (most recent call last):
  File "/Users/lucabertini/Documents/GitHub/RT/riffusion_api/riffusion_api/api.py", line 423, in generate
    track = self._wait_for_generate(account=account, job_id=json_data['job_id'])
            ^^^^^^^^^^^^^^^^^^^^^^^^^^^^^^^^^^^^^^^^^^^^^^^^^^^^^^^^^^^^^^^^^^^^
  File "/Users/lucabertini/Documents/GitHub/RT/riffusion_api/riffusion_api/api.py", line 254, in _wait_for_generate
    response.raise_for_status()
  File "/Users/lucabertini/Documents/GitHub/RT/riffusion_api/venv/lib/python3.12/site-packages/requests/models.py", line 1024, in raise_for_status
    raise HTTPError(http_error_msg, response=self)
requests.exceptions.HTTPError: 502 Server Error: Bad Gateway for url: https://wb.riffusion.com/v2/generate/d112bb6e-7c93-4dd4-8846-fdec90a5d226

(11.02.22.23)Selected: lucabertiniluca@gmail.com
(11.02.22.24)Error 3/10 while generation: Traceback (most recent call last):
  File "/Users/lucabertini/Documents/GitHub/RT/riffusion_api/venv/lib/python3.12/site-packages/requests/models.py", line 974, in json
    return complexjson.loads(self.text, **kwargs)
           ^^^^^^^^^^^^^^^^^^^^^^^^^^^^^^^^^^^^^^
  File "/opt/homebrew/Cellar/python@3.12/3.12.9/Frameworks/Python.framework/Versions/3.12/lib/python3.12/json/__init__.py", line 346, in loads
    return _default_decoder.decode(s)
           ^^^^^^^^^^^^^^^^^^^^^^^^^^
  File "/opt/homebrew/Cellar/python@3.12/3.12.9/Frameworks/Python.framework/Versions/3.12/lib/python3.12/json/decoder.py", line 338, in decode
    obj, end = self.raw_decode(s, idx=_w(s, 0).end())
               ^^^^^^^^^^^^^^^^^^^^^^^^^^^^^^^^^^^^^^
  File "/opt/homebrew/Cellar/python@3.12/3.12.9/Frameworks/Python.framework/Versions/3.12/lib/python3.12/json/decoder.py", line 356, in raw_decode
    raise JSONDecodeError("Expecting value", s, err.value) from None
json.decoder.JSONDecodeError: Expecting value: line 2 column 1 (char 1)

During handling of the above exception, another exception occurred:

Traceback (most recent call last):
  File "/Users/lucabertini/Documents/GitHub/RT/riffusion_api/riffusion_api/api.py", line 422, in generate
    json_data = response.json()
                ^^^^^^^^^^^^^^^
  File "/Users/lucabertini/Documents/GitHub/RT/riffusion_api/venv/lib/python3.12/site-packages/requests/models.py", line 978, in json
    raise RequestsJSONDecodeError(e.msg, e.doc, e.pos)
requests.exceptions.JSONDecodeError: Expecting value: line 2 column 1 (char 1)

(11.02.22.24)Selected: lucabertiniluca@gmail.com
(11.02.22.25)Error 4/10 while generation: Traceback (most recent call last):
  File "/Users/lucabertini/Documents/GitHub/RT/riffusion_api/riffusion_api/api.py", line 423, in generate
    track = self._wait_for_generate(account=account, job_id=json_data['job_id'])
            ^^^^^^^^^^^^^^^^^^^^^^^^^^^^^^^^^^^^^^^^^^^^^^^^^^^^^^^^^^^^^^^^^^^^
  File "/Users/lucabertini/Documents/GitHub/RT/riffusion_api/riffusion_api/api.py", line 254, in _wait_for_generate
    response.raise_for_status()
  File "/Users/lucabertini/Documents/GitHub/RT/riffusion_api/venv/lib/python3.12/site-packages/requests/models.py", line 1024, in raise_for_status
    raise HTTPError(http_error_msg, response=self)
requests.exceptions.HTTPError: 502 Server Error: Bad Gateway for url: https://wb.riffusion.com/v2/generate/387401b1-c839-40bf-a5c1-e0ad4272d870

(11.02.22.25)Selected: lucabertiniluca@gmail.com
(11.02.22.26)Skip refresh lucabertiniluca@gmail.com
(11.02.22.26)Login to (1/1 account)
(11.02.22.26)Error in login new account: Traceback (most recent call last):
  File "/Users/lucabertini/Documents/GitHub/RT/riffusion_api/riffusion_api/api.py", line 100, in create_account_database
    new_account = RiffusionAccount(sb_api_auth_token_0)
                  ^^^^^^^^^^^^^^^^^^^^^^^^^^^^^^^^^^^^^
  File "/Users/lucabertini/Documents/GitHub/RT/riffusion_api/riffusion_api/_types/types.py", line 109, in __init__
    self.login_info = RiffusionLoginInfo(sb_api_auth_token_0.replace("base64-", ""))
                      ^^^^^^^^^^^^^^^^^^^^^^^^^^^^^^^^^^^^^^^^^^^^^^^^^^^^^^^^^^^^^^
  File "/Users/lucabertini/Documents/GitHub/RT/riffusion_api/riffusion_api/_types/types.py", line 91, in __init__
    json_data = decode_and_parse_invalid_base64(data)
                ^^^^^^^^^^^^^^^^^^^^^^^^^^^^^^^^^^^^^
  File "/Users/lucabertini/Documents/GitHub/RT/riffusion_api/riffusion_api/s_utils.py", line 31, in decode_and_parse_invalid_base64
    parsed_data = json.loads(decoded_str)
                  ^^^^^^^^^^^^^^^^^^^^^^^
  File "/opt/homebrew/Cellar/python@3.12/3.12.9/Frameworks/Python.framework/Versions/3.12/lib/python3.12/json/__init__.py", line 346, in loads
    return _default_decoder.decode(s)
           ^^^^^^^^^^^^^^^^^^^^^^^^^^
  File "/opt/homebrew/Cellar/python@3.12/3.12.9/Frameworks/Python.framework/Versions/3.12/lib/python3.12/json/decoder.py", line 338, in decode
    obj, end = self.raw_decode(s, idx=_w(s, 0).end())
               ^^^^^^^^^^^^^^^^^^^^^^^^^^^^^^^^^^^^^^
  File "/opt/homebrew/Cellar/python@3.12/3.12.9/Frameworks/Python.framework/Versions/3.12/lib/python3.12/json/decoder.py", line 354, in raw_decode
    obj, end = self.scan_once(s, idx)
               ^^^^^^^^^^^^^^^^^^^^^^
json.decoder.JSONDecodeError: Expecting property name enclosed in double quotes: line 1 column 1726 (char 1725)

(11.02.22.26)saved 1 accounts
(11.02.22.26)File /Users/lucabertini/Documents/GitHub/RT/riffusion_api/song.mp3 exists. It will be removed
(11.02.22.26)Selected: lucabertiniluca@gmail.com
(11.02.22.26)Skip refresh lucabertiniluca@gmail.com
(11.02.22.26)Login to (1/1 account)
(11.02.22.26)Error in login new account: Traceback (most recent call last):
  File "/Users/lucabertini/Documents/GitHub/RT/riffusion_api/riffusion_api/api.py", line 100, in create_account_database
    new_account = RiffusionAccount(sb_api_auth_token_0)
                  ^^^^^^^^^^^^^^^^^^^^^^^^^^^^^^^^^^^^^
  File "/Users/lucabertini/Documents/GitHub/RT/riffusion_api/riffusion_api/_types/types.py", line 109, in __init__
    self.login_info = RiffusionLoginInfo(sb_api_auth_token_0.replace("base64-", ""))
                      ^^^^^^^^^^^^^^^^^^^^^^^^^^^^^^^^^^^^^^^^^^^^^^^^^^^^^^^^^^^^^^
  File "/Users/lucabertini/Documents/GitHub/RT/riffusion_api/riffusion_api/_types/types.py", line 91, in __init__
    json_data = decode_and_parse_invalid_base64(data)
                ^^^^^^^^^^^^^^^^^^^^^^^^^^^^^^^^^^^^^
  File "/Users/lucabertini/Documents/GitHub/RT/riffusion_api/riffusion_api/s_utils.py", line 31, in decode_and_parse_invalid_base64
    parsed_data = json.loads(decoded_str)
                  ^^^^^^^^^^^^^^^^^^^^^^^
  File "/opt/homebrew/Cellar/python@3.12/3.12.9/Frameworks/Python.framework/Versions/3.12/lib/python3.12/json/__init__.py", line 346, in loads
    return _default_decoder.decode(s)
           ^^^^^^^^^^^^^^^^^^^^^^^^^^
  File "/opt/homebrew/Cellar/python@3.12/3.12.9/Frameworks/Python.framework/Versions/3.12/lib/python3.12/json/decoder.py", line 338, in decode
    obj, end = self.raw_decode(s, idx=_w(s, 0).end())
               ^^^^^^^^^^^^^^^^^^^^^^^^^^^^^^^^^^^^^^
  File "/opt/homebrew/Cellar/python@3.12/3.12.9/Frameworks/Python.framework/Versions/3.12/lib/python3.12/json/decoder.py", line 354, in raw_decode
    obj, end = self.scan_once(s, idx)
               ^^^^^^^^^^^^^^^^^^^^^^
json.decoder.JSONDecodeError: Expecting property name enclosed in double quotes: line 1 column 1726 (char 1725)

(11.02.22.26)saved 1 accounts
(11.02.22.26)File /Users/lucabertini/Documents/GitHub/RT/riffusion_api/song.mp3 exists. It will be removed
(11.02.22.26)Selected: lucabertiniluca@gmail.com
(11.02.22.26)Skip refresh lucabertiniluca@gmail.com
(11.02.22.26)Login to (1/1 account)
(11.02.22.26)Skip account as exists
(11.02.22.26)saved 1 accounts
(11.02.22.26)File /Users/lucabertini/Documents/GitHub/RT/riffusion_api/song.mp3 exists. It will be removed
(11.02.22.26)Selected: lucabertiniluca@gmail.com
(11.02.22.27)Error 1/10 while generation: Traceback (most recent call last):
  File "/Users/lucabertini/Documents/GitHub/RT/riffusion_api/venv/lib/python3.12/site-packages/requests/models.py", line 974, in json
    return complexjson.loads(self.text, **kwargs)
           ^^^^^^^^^^^^^^^^^^^^^^^^^^^^^^^^^^^^^^
  File "/opt/homebrew/Cellar/python@3.12/3.12.9/Frameworks/Python.framework/Versions/3.12/lib/python3.12/json/__init__.py", line 346, in loads
    return _default_decoder.decode(s)
           ^^^^^^^^^^^^^^^^^^^^^^^^^^
  File "/opt/homebrew/Cellar/python@3.12/3.12.9/Frameworks/Python.framework/Versions/3.12/lib/python3.12/json/decoder.py", line 338, in decode
    obj, end = self.raw_decode(s, idx=_w(s, 0).end())
               ^^^^^^^^^^^^^^^^^^^^^^^^^^^^^^^^^^^^^^
  File "/opt/homebrew/Cellar/python@3.12/3.12.9/Frameworks/Python.framework/Versions/3.12/lib/python3.12/json/decoder.py", line 356, in raw_decode
    raise JSONDecodeError("Expecting value", s, err.value) from None
json.decoder.JSONDecodeError: Expecting value: line 2 column 1 (char 1)

During handling of the above exception, another exception occurred:

Traceback (most recent call last):
  File "/Users/lucabertini/Documents/GitHub/RT/riffusion_api/riffusion_api/api.py", line 422, in generate
    json_data = response.json()
                ^^^^^^^^^^^^^^^
  File "/Users/lucabertini/Documents/GitHub/RT/riffusion_api/test.py", line 12, in debug_json
    return original_json(self, **kwargs)
           ^^^^^^^^^^^^^^^^^^^^^^^^^^^^^
  File "/Users/lucabertini/Documents/GitHub/RT/riffusion_api/venv/lib/python3.12/site-packages/requests/models.py", line 978, in json
    raise RequestsJSONDecodeError(e.msg, e.doc, e.pos)
requests.exceptions.JSONDecodeError: Expecting value: line 2 column 1 (char 1)

(11.02.22.27)Selected: lucabertiniluca@gmail.com
(11.02.22.27)Error 2/10 while generation: Traceback (most recent call last):
  File "/Users/lucabertini/Documents/GitHub/RT/riffusion_api/venv/lib/python3.12/site-packages/requests/models.py", line 974, in json
    return complexjson.loads(self.text, **kwargs)
           ^^^^^^^^^^^^^^^^^^^^^^^^^^^^^^^^^^^^^^
  File "/opt/homebrew/Cellar/python@3.12/3.12.9/Frameworks/Python.framework/Versions/3.12/lib/python3.12/json/__init__.py", line 346, in loads
    return _default_decoder.decode(s)
           ^^^^^^^^^^^^^^^^^^^^^^^^^^
  File "/opt/homebrew/Cellar/python@3.12/3.12.9/Frameworks/Python.framework/Versions/3.12/lib/python3.12/json/decoder.py", line 338, in decode
    obj, end = self.raw_decode(s, idx=_w(s, 0).end())
               ^^^^^^^^^^^^^^^^^^^^^^^^^^^^^^^^^^^^^^
  File "/opt/homebrew/Cellar/python@3.12/3.12.9/Frameworks/Python.framework/Versions/3.12/lib/python3.12/json/decoder.py", line 356, in raw_decode
    raise JSONDecodeError("Expecting value", s, err.value) from None
json.decoder.JSONDecodeError: Expecting value: line 2 column 1 (char 1)

During handling of the above exception, another exception occurred:

Traceback (most recent call last):
  File "/Users/lucabertini/Documents/GitHub/RT/riffusion_api/riffusion_api/api.py", line 422, in generate
    json_data = response.json()
                ^^^^^^^^^^^^^^^
  File "/Users/lucabertini/Documents/GitHub/RT/riffusion_api/test.py", line 12, in debug_json
    return original_json(self, **kwargs)
           ^^^^^^^^^^^^^^^^^^^^^^^^^^^^^
  File "/Users/lucabertini/Documents/GitHub/RT/riffusion_api/venv/lib/python3.12/site-packages/requests/models.py", line 978, in json
    raise RequestsJSONDecodeError(e.msg, e.doc, e.pos)
requests.exceptions.JSONDecodeError: Expecting value: line 2 column 1 (char 1)

(11.02.22.27)Selected: lucabertiniluca@gmail.com
(11.02.22.28)Skip refresh lucabertiniluca@gmail.com
(11.02.22.28)Login to (1/1 account)
(11.02.22.28)Skip account as exists
(11.02.22.28)saved 1 accounts
(11.02.22.28)File /Users/lucabertini/Documents/GitHub/RT/riffusion_api/song.mp3 exists. It will be removed
(11.02.22.28)Selected: lucabertiniluca@gmail.com
(11.02.22.34)Skip refresh lucabertiniluca@gmail.com
(11.02.22.34)Login to (1/1 account)
(11.02.22.34)Skip account as exists
(11.02.22.34)saved 1 accounts
(11.02.22.35)Skip refresh lucabertiniluca@gmail.com
(11.02.22.35)Login to (1/1 account)
(11.02.22.35)Skip account as exists
(11.02.22.35)saved 1 accounts
(11.02.22.36)Skip refresh lucabertiniluca@gmail.com
(11.02.22.36)Login to (1/1 account)
(11.02.22.36)Skip account as exists
(11.02.22.36)saved 1 accounts
(11.02.22.36)File /Users/lucabertini/Documents/GitHub/RT/riffusion_api/song.mp3 exists. It will be removed
(11.02.22.36)Selected: lucabertiniluca@gmail.com
(11.02.22.39)Skip refresh lucabertiniluca@gmail.com
(11.02.22.39)Login to (1/1 account)
(11.02.22.39)Skip account as exists
(11.02.22.39)saved 1 accounts
(11.02.22.39)File /Users/lucabertini/Documents/GitHub/RT/riffusion_api/song.mp3 exists. It will be removed
(11.02.22.39)Selected: lucabertiniluca@gmail.com
(11.02.22.42)Skip refresh lucabertiniluca@gmail.com
(11.02.22.42)Login to (1/1 account)
(11.02.22.42)Skip account as exists
(11.02.22.42)saved 1 accounts
(11.02.22.42)File /Users/lucabertini/Documents/GitHub/RT/riffusion_api/song.mp3 exists. It will be removed
(11.02.22.42)Selected: lucabertiniluca@gmail.com
(12.02.11.50)Skip refresh lucabertiniluca@gmail.com
(12.02.11.50)Login to (1/1 account)
(12.02.11.50)Error in login new account: Traceback (most recent call last):
  File "/Users/lucabertini/Documents/GitHub/RT/riffusion_api/riffusion_api/api.py", line 100, in create_account_database
    new_account = RiffusionAccount(sb_api_auth_token_0)
                  ^^^^^^^^^^^^^^^^^^^^^^^^^^^^^^^^^^^^^
  File "/Users/lucabertini/Documents/GitHub/RT/riffusion_api/riffusion_api/_types/types.py", line 109, in __init__
    self.login_info = RiffusionLoginInfo(sb_api_auth_token_0.replace("base64-", ""))
                      ^^^^^^^^^^^^^^^^^^^^^^^^^^^^^^^^^^^^^^^^^^^^^^^^^^^^^^^^^^^^^^
  File "/Users/lucabertini/Documents/GitHub/RT/riffusion_api/riffusion_api/_types/types.py", line 91, in __init__
    json_data = decode_and_parse_invalid_base64(data)
                ^^^^^^^^^^^^^^^^^^^^^^^^^^^^^^^^^^^^^
  File "/Users/lucabertini/Documents/GitHub/RT/riffusion_api/riffusion_api/s_utils.py", line 31, in decode_and_parse_invalid_base64
    parsed_data = json.loads(decoded_str)
                  ^^^^^^^^^^^^^^^^^^^^^^^
  File "/opt/homebrew/Cellar/python@3.12/3.12.9/Frameworks/Python.framework/Versions/3.12/lib/python3.12/json/__init__.py", line 346, in loads
    return _default_decoder.decode(s)
           ^^^^^^^^^^^^^^^^^^^^^^^^^^
  File "/opt/homebrew/Cellar/python@3.12/3.12.9/Frameworks/Python.framework/Versions/3.12/lib/python3.12/json/decoder.py", line 338, in decode
    obj, end = self.raw_decode(s, idx=_w(s, 0).end())
               ^^^^^^^^^^^^^^^^^^^^^^^^^^^^^^^^^^^^^^
  File "/opt/homebrew/Cellar/python@3.12/3.12.9/Frameworks/Python.framework/Versions/3.12/lib/python3.12/json/decoder.py", line 354, in raw_decode
    obj, end = self.scan_once(s, idx)
               ^^^^^^^^^^^^^^^^^^^^^^
json.decoder.JSONDecodeError: Unterminated string starting at: line 1 column 17 (char 16)

(12.02.11.50)saved 1 accounts
(12.02.11.50)File /Users/lucabertini/Documents/GitHub/RT/riffusion_api/song.mp3 exists. It will be removed
(12.02.11.50)Selected: lucabertiniluca@gmail.com
